
1. try {} catch {} out_range_of， 抛出异常后面的代码是执行不到的
	- 解决方案1， 在每行j.at(xxx)进行try ... catch的捕捉
